Workbook

Sheet How to Use
A1: BUSINESS PLAN SIMULATOR | HOW TO USE THIS TOOL
A2: Designed for VFU Business Students — Developed for Strategic Thinking & Financial Analysis
A4: ① WHAT IS THIS TOOL?
B5: This simulator helps you build a 5-year financial plan for your business idea — without doing manual accounting. You focus on STRATEGY: What is your target market? What price will you charge? How will your costs evolve? The tool automatically generates your Profit & Loss Statement (P&L), Break-Even Analysis (BEP), and Payback Period chart.
A7: ② HOW TO USE — STEP BY STEP
B8: STEP 1 — Go to the "Inputs" sheet | C8: This is the ONLY sheet where you type numbers. All other sheets update automatically. Blue text on yellow background = your input cells.
B10: STEP 2 — Revenue Assumptions (Section 1) | C10: For each year, enter: (a) total market growth rate, (b) your target market share, (c) unit selling price. Year 1 market size is your starting estimate; Years 2-5 auto-calculate.
B12: STEP 3 — Variable Costs (Section 2) | C12: Enter the cost PER UNIT SOLD for each item, for each of the 5 years. These costs rise when you sell more and fall when you sell less.
B14: STEP 4 — Fixed Costs (Section 3) | C14: Enter the ANNUAL total for each fixed cost item, for each year. Fixed costs do NOT change with sales volume. Depreciation is automatically calculated from your investments and added here.
B16: STEP 5 — Investment (Section 4) | C16: Enter one-time investments for ANY year (Year 1 to Year 5). Investments ≥ USD 1,000 are automatically depreciated (1/5 per year from purchase year). Smaller investments are expensed in full in the purchase year. Both are automatically added to Fixed Costs — you do not need to enter them manually.
B18: STEP 6 — Read your results | C18: Open the "PL" sheet for your 5-year P&L and charts. Open the "BEP" sheet for Break-Even and Payback Period analysis.
A21: ③ COLOUR CODING GUIDE
B22: BLUE TEXT on YELLOW background | C22: → Your input cells — enter assumptions here
B23: BLACK TEXT on GREEN background (Inputs sheet) | C23: → Auto-calculated in same sheet — do not edit
B24: BLUE-ITALIC TEXT on LIGHT BLUE (Inputs: Depreciation) | C24: → Auto-calculated from your investment entries
B25: BOLD TEXT on LIGHT GREEN background | C25: → Key profit rows and BEP results
B26: BOLD TEXT on LIGHT BLUE background | C26: → Subtotal / Total rows
B27: GREEN TEXT (in PL and BEP sheets) | C27: → Values linked automatically from another sheet
A29: ④ KEY CONCEPTS & FORMULAS
B30: Market Size × Market Share | C30: → Units Sold (your business volume each year)
B31: Units Sold × Unit Price | C31: → Revenue (your total sales income)
B32: Revenue − Total Variable Costs | C32: → Gross Profit
B33: Gross Profit − Total Fixed Costs | C33: → Operating Profit / EBIT (Fixed Costs include Depreciation)
B34: Investment ≥ $1,000 ÷ 5 years | C34: → Annual Depreciation (auto-added to Fixed Costs)
B35: Investment < $1,000 | C35: → Expensed in full in the year of purchase (auto-added to Fixed Costs)
B36: Unit Price − Variable Cost per Unit | C36: → Contribution Margin per Unit
B37: Fixed Costs ÷ Contribution Margin / Unit | C37: → BEP in Units (minimum sales to break even)
B38: BEP Units × Unit Price | C38: → BEP in Revenue ($)
B39: Cumulative Revenue = Cumulative Costs | C39: → Payback Year (full cost recovery point)
A41: ⑤ ANALYTICAL TIPS
B42: 💡 JUSTIFY your assumptions. Why this growth rate? Why this market share? What is your evidence?
B43: 💡 SCENARIO THINKING: What if price drops in Year 3? What if costs rise faster than expected? Model it.
B44: 💡 If BEP > your sales target, your business model needs redesigning — change STRATEGY, not just numbers.
B45: 💡 Losses in Years 1-2 are normal for a start-up. The key question: WHEN does the business turn profitable?
B46: 💡 Plan investments strategically. A large Year 3 investment increases depreciation in Years 3-5, raising your BEP.
B47: 💡 Watch the PAYBACK chart — does cumulative revenue cross cumulative costs by Year 5?

Sheet Inputs
A1: BUSINESS PLAN SIMULATOR — INPUT ASSUMPTIONS (Enter values in the BLUE cells only)
A2: 🔵 BLUE on YELLOW = your input | Green bg = auto-calculated | Blue-italic = depreciation (auto) | All values in USD ($)
A4: SECTION 1 ► MARKET & REVENUE ASSUMPTIONS (enter for each year separately)
A5: Item | B5: Year 1 | C5: Year 2 | D5: Year 3 | E5: Year 4 | F5: Year 5 | G5: Notes / Guidance
A6: Market Growth Rate (%) | B6: — Base Year — | C6: 0.05 | D6: 0.08 | E6: 0.1 | F6: 0.15 | G6: Annual growth of the TOTAL market vs. prior year (e.g. 0.10 = 10%)
A7: Total Market Size (units) | B7: 100000 | C7: =ROUND(B7*(1+C6),0) -> 105000 | D7: =ROUND(C7*(1+D6),0) -> 113400 | E7: =ROUND(D7*(1+E6),0) -> 124740 | F7: =ROUND(E7*(1+F6),0) -> 143451 | G7: Year 1: your estimate of the WHOLE market. Years 2-5: auto from growth rate.
A8: Your Target Market Share (%) | B8: 0.05 | C8: 0.07 | D8: 0.2 | E8: 0.25 | F8: 0.4 | G8: What % of the total market will YOUR business capture?
A9: Unit Selling Price (USD) | B9: 15 | C9: 15 | D9: 30 | E9: 30 | F9: 35 | G9: Your price per unit. Can change each year.
A10: ▶ Units Sold [AUTO] | B10: =ROUND(B7*B8,0) -> 5000 | C10: =ROUND(C7*C8,0) -> 7350 | D10: =ROUND(D7*D8,0) -> 22680 | E10: =ROUND(E7*E8,0) -> 31185 | F10: =ROUND(F7*F8,0) -> 57380 | G10: AUTO: Market Size × Market Share.
A11: ▶ REVENUE ($) [AUTO] | B11: =B10*B9 -> 75000 | C11: =C10*C9 -> 110250 | D11: =D10*D9 -> 680400 | E11: =E10*E9 -> 935550 | F11: =F10*F9 -> 2008300 | G11: AUTO: Units Sold × Unit Price.
A13: SECTION 2 ► VARIABLE COSTS (cost per unit sold, USD — enter for each year separately)
A14: Cost Item | B14: Year 1 ($ / unit) | C14: Year 2 ($ / unit) | D14: Year 3 ($ / unit) | E14: Year 4 ($ / unit) | F14: Year 5 ($ / unit) | G14: Notes
A15: Raw Materials / Cost of Goods | B15: 8 | C15: 8 | D15: 8 | E15: 8 | F15: 8 | G15: Direct material & production cost per unit sold
A16: Marketing & Promotion | B16: 2 | C16: 2 | D16: 2 | E16: 2 | F16: 2 | G16: Variable marketing spend per unit
A17: Distribution / Logistics | B17: 1.5 | C17: 1.5 | D17: 1.5 | E17: 1.5 | F17: 1.5 | G17: Shipping, delivery & handling per unit
G18: ← Add your own variable cost item here
G19: ← Add your own variable cost item here
G20: ← Add your own variable cost item here
A21: ▶ Total Variable Cost per Unit [AUTO] | B21: =IFERROR(SUM(B15:B20),0) -> 11.5 | C21: =IFERROR(SUM(C15:C20),0) -> 11.5 | D21: =IFERROR(SUM(D15:D20),0) -> 11.5 | E21: =IFERROR(SUM(E15:E20),0) -> 11.5 | F21: =IFERROR(SUM(F15:F20),0) -> 11.5 | G21: AUTO: Sum of all variable cost items above.
A23: SECTION 3 ► FIXED COSTS (annual total, USD — enter for each year separately)
A24: Cost Item | B24: Year 1 ($ / year) | C24: Year 2 ($ / year) | D24: Year 3 ($ / year) | E24: Year 4 ($ / year) | F24: Year 5 ($ / year) | G24: Notes
A25: Rent / Office Space | B25: 12000 | C25: 12000 | D25: 12000 | E25: 12000 | F25: 12000 | G25: Annual rent. Increase if you expand premises.
A26: Staff Salaries (total) | B26: 48000 | C26: 48000 | D26: 48000 | E26: 60000 | F26: 60000 | G26: All employees combined. Rises as you hire more.
A27: Utilities & Communications | B27: 3600 | C27: 3600 | D27: 3600 | E27: 3600 | F27: 3600 | G27: Electricity, internet, phone — full year total.
A28: Insurance | B28: 2400 | C28: 2400 | D28: 2400 | E28: 2400 | F28: 2400 | G28: Business insurance premium — annual.
G29: ← Add your own fixed cost item here
G30: ← Add your own fixed cost item here
G31: ← Add your own fixed cost item here
A32: ▶ Depreciation & Investment Expense [AUTO] | B32: =SUMPRODUCT((B38:B43>=1000)*(B38:B43)/5)+SUMPRODUCT((B38:B43>0)*(B38:B43<1000)*(B38:B43)) -> 5300 | C32: =SUMPRODUCT((B38:B43>=1000)*(B38:B43)/5)+SUMPRODUCT((C38:C43>=1000)*(C38:C43)/5)+SUMPRODUCT((C38:C43>0)*(C38:C43<1000)*(C38:C43)) -> 5300 | D32: =SUMPRODUCT((B38:B43>=1000)*(B38:B43)/5)+SUMPRODUCT((C38:C43>=1000)*(C38:C43)/5)+SUMPRODUCT((D38:D43>=1000)*(D38:D43)/5)+SUMPRODUCT((D38:D43>0)*(D38:D43<1000)*(D38:D43)) -> 6300 | E32: =SUMPRODUCT((B38:B43>=1000)*(B38:B43)/5)+SUMPRODUCT((C38:C43>=1000)*(C38:C43)/5)+SUMPRODUCT((D38:D43>=1000)*(D38:D43)/5)+SUMPRODUCT((E38:E43>=1000)*(E38:E43)/5)+SUMPRODUCT((E38:E43>0)*(E38:E43<1000)*(E38:E43)) -> 6300 | F32: =SUMPRODUCT((B38:B43>=1000)*(B38:B43)/5)+SUMPRODUCT((C38:C43>=1000)*(C38:C43)/5)+SUMPRODUCT((D38:D43>=1000)*(D38:D43)/5)+SUMPRODUCT((E38:E43>=1000)*(E38:E43)/5)+SUMPRODUCT((F38:F43>=1000)*(F38:F43)/5)+SUMPRODUCT((F38:F43>0)*(F38:F43<1000)*(F38:F43)) -> 7300 | G32: AUTO: From Section 4 below. Items ≥ $1,000 → 1/5 per year from purchase year. Items < $1,000 → full amount in purchase year.
A33: ▶ Total Fixed Costs incl. Depreciation [AUTO] | B33: =IFERROR(SUM(B25:B32),0) -> 71300 | C33: =IFERROR(SUM(C25:C32),0) -> 71300 | D33: =IFERROR(SUM(D25:D32),0) -> 72300 | E33: =IFERROR(SUM(E25:E32),0) -> 84300 | F33: =IFERROR(SUM(F25:F32),0) -> 85300 | G33: AUTO: Sum of all fixed costs + depreciation above.
A35: SECTION 4 ► INVESTMENT (enter in the year the investment is made)
A36: ⚠ RULE: Investments ≥ USD 1,000 → depreciated straight-line over 5 years from purchase year (annual depreciation = amount ÷ 5). Investments < USD 1,000 → expensed in full in purchase year. Both are automatically included in Fixed Costs above — no manual entry needed.
A37: Investment Item | B37: Year 1 (USD) | C37: Year 2 (USD) | D37: Year 3 (USD) | E37: Year 4 (USD) | F37: Year 5 (USD) | G37: Notes
A38: Equipment / Machinery | B38: 20000 | D38: 5000 | F38: 5000 | G38: Production equipment, tools, machinery
A39: Computer / Technology | B39: 5000 | G39: Laptops, software licences, IT setup
A40: Furniture & Fixtures | B40: 1500 | G40: Desks, chairs, shelving, displays
G41: ← Add your own investment item here
G42: ← Add your own investment item here
G43: ← Add your own investment item here
A44: ▶ Total Investment per Year [AUTO] | B44: =IFERROR(SUM(B38:B43),0) -> 26500 | C44: =IFERROR(SUM(C38:C43),0) -> 0 | D44: =IFERROR(SUM(D38:D43),0) -> 5000 | E44: =IFERROR(SUM(E38:E43),0) -> 0 | F44: =IFERROR(SUM(F38:F43),0) -> 5000

Sheet PL
A1: PROFIT & LOSS STATEMENT — 5-YEAR PROJECTION (Auto-calculated from Inputs sheet)
A2: All values in USD ($). Do NOT type in this sheet — change assumptions in Inputs only.
A3: Item | B3: Year 1 | C3: Year 2 | D3: Year 3 | E3: Year 4 | F3: Year 5
A4: REVENUE
A5: Total Market Size (units) | B5: =Inputs!B7 -> 100000 | C5: =Inputs!C7 -> 105000 | D5: =Inputs!D7 -> 113400 | E5: =Inputs!E7 -> 124740 | F5: =Inputs!F7 -> 143451
A6: Market Share (%) | B6: =Inputs!B8 -> 0.05 | C6: =Inputs!C8 -> 0.07 | D6: =Inputs!D8 -> 0.2 | E6: =Inputs!E8 -> 0.25 | F6: =Inputs!F8 -> 0.4
A7: Units Sold | B7: =Inputs!B10 -> 5000 | C7: =Inputs!C10 -> 7350 | D7: =Inputs!D10 -> 22680 | E7: =Inputs!E10 -> 31185 | F7: =Inputs!F10 -> 57380
A8: Unit Selling Price (USD) | B8: =Inputs!B9 -> 15 | C8: =Inputs!C9 -> 15 | D8: =Inputs!D9 -> 30 | E8: =Inputs!E9 -> 30 | F8: =Inputs!F9 -> 35
A9: REVENUE | B9: =Inputs!B11 -> 75000 | C9: =Inputs!C11 -> 110250 | D9: =Inputs!D11 -> 680400 | E9: =Inputs!E11 -> 935550 | F9: =Inputs!F11 -> 2008300
A10: VARIABLE COSTS (cost per unit × units sold)
A11: =IF(Inputs!A15=""," (add label in Inputs)",Inputs!A15) -> Raw Materials / Cost of Goods | B11: =IFERROR(Inputs!B15*Inputs!B10,0) -> 40000 | C11: =IFERROR(Inputs!C15*Inputs!C10,0) -> 58800 | D11: =IFERROR(Inputs!D15*Inputs!D10,0) -> 181440 | E11: =IFERROR(Inputs!E15*Inputs!E10,0) -> 249480 | F11: =IFERROR(Inputs!F15*Inputs!F10,0) -> 459040
A12: =IF(Inputs!A16=""," (add label in Inputs)",Inputs!A16) -> Marketing & Promotion | B12: =IFERROR(Inputs!B16*Inputs!B10,0) -> 10000 | C12: =IFERROR(Inputs!C16*Inputs!C10,0) -> 14700 | D12: =IFERROR(Inputs!D16*Inputs!D10,0) -> 45360 | E12: =IFERROR(Inputs!E16*Inputs!E10,0) -> 62370 | F12: =IFERROR(Inputs!F16*Inputs!F10,0) -> 114760
A13: =IF(Inputs!A17=""," (add label in Inputs)",Inputs!A17) -> Distribution / Logistics | B13: =IFERROR(Inputs!B17*Inputs!B10,0) -> 7500 | C13: =IFERROR(Inputs!C17*Inputs!C10,0) -> 11025 | D13: =IFERROR(Inputs!D17*Inputs!D10,0) -> 34020 | E13: =IFERROR(Inputs!E17*Inputs!E10,0) -> 46777.5 | F13: =IFERROR(Inputs!F17*Inputs!F10,0) -> 86070
A14: =IF(Inputs!A18=""," (add label in Inputs)",Inputs!A18) -> (add label in Inputs) | B14: =IFERROR(Inputs!B18*Inputs!B10,0) -> 0 | C14: =IFERROR(Inputs!C18*Inputs!C10,0) -> 0 | D14: =IFERROR(Inputs!D18*Inputs!D10,0) -> 0 | E14: =IFERROR(Inputs!E18*Inputs!E10,0) -> 0 | F14: =IFERROR(Inputs!F18*Inputs!F10,0) -> 0
A15: =IF(Inputs!A19=""," (add label in Inputs)",Inputs!A19) -> (add label in Inputs) | B15: =IFERROR(Inputs!B19*Inputs!B10,0) -> 0 | C15: =IFERROR(Inputs!C19*Inputs!C10,0) -> 0 | D15: =IFERROR(Inputs!D19*Inputs!D10,0) -> 0 | E15: =IFERROR(Inputs!E19*Inputs!E10,0) -> 0 | F15: =IFERROR(Inputs!F19*Inputs!F10,0) -> 0
A16: =IF(Inputs!A20=""," (add label in Inputs)",Inputs!A20) -> (add label in Inputs) | B16: =IFERROR(Inputs!B20*Inputs!B10,0) -> 0 | C16: =IFERROR(Inputs!C20*Inputs!C10,0) -> 0 | D16: =IFERROR(Inputs!D20*Inputs!D10,0) -> 0 | E16: =IFERROR(Inputs!E20*Inputs!E10,0) -> 0 | F16: =IFERROR(Inputs!F20*Inputs!F10,0) -> 0
A17: Total Variable Costs | B17: =SUM(B11:B16) -> 57500 | C17: =SUM(C11:C16) -> 84525 | D17: =SUM(D11:D16) -> 260820 | E17: =SUM(E11:E16) -> 358627.5 | F17: =SUM(F11:F16) -> 659870
A18: GROSS PROFIT | B18: =B9-B17 -> 17500 | C18: =C9-C17 -> 25725 | D18: =D9-D17 -> 419580 | E18: =E9-E17 -> 576922.5 | F18: =F9-F17 -> 1348430
A19: Gross Margin (%) | B19: =IFERROR(B18/B9,0) -> 0.23333333 | C19: =IFERROR(C18/C9,0) -> 0.23333333 | D19: =IFERROR(D18/D9,0) -> 0.61666667 | E19: =IFERROR(E18/E9,0) -> 0.61666667 | F19: =IFERROR(F18/F9,0) -> 0.67142857
A21: FIXED COSTS (including Depreciation — auto-calculated from Inputs)
A22: =IF(Inputs!A25=""," (add label in Inputs)",Inputs!A25) -> Rent / Office Space | B22: =IFERROR(Inputs!B25,0) -> 12000 | C22: =IFERROR(Inputs!C25,0) -> 12000 | D22: =IFERROR(Inputs!D25,0) -> 12000 | E22: =IFERROR(Inputs!E25,0) -> 12000 | F22: =IFERROR(Inputs!F25,0) -> 12000
A23: =IF(Inputs!A26=""," (add label in Inputs)",Inputs!A26) -> Staff Salaries (total) | B23: =IFERROR(Inputs!B26,0) -> 48000 | C23: =IFERROR(Inputs!C26,0) -> 48000 | D23: =IFERROR(Inputs!D26,0) -> 48000 | E23: =IFERROR(Inputs!E26,0) -> 60000 | F23: =IFERROR(Inputs!F26,0) -> 60000
A24: =IF(Inputs!A27=""," (add label in Inputs)",Inputs!A27) -> Utilities & Communications | B24: =IFERROR(Inputs!B27,0) -> 3600 | C24: =IFERROR(Inputs!C27,0) -> 3600 | D24: =IFERROR(Inputs!D27,0) -> 3600 | E24: =IFERROR(Inputs!E27,0) -> 3600 | F24: =IFERROR(Inputs!F27,0) -> 3600
A25: =IF(Inputs!A28=""," (add label in Inputs)",Inputs!A28) -> Insurance | B25: =IFERROR(Inputs!B28,0) -> 2400 | C25: =IFERROR(Inputs!C28,0) -> 2400 | D25: =IFERROR(Inputs!D28,0) -> 2400 | E25: =IFERROR(Inputs!E28,0) -> 2400 | F25: =IFERROR(Inputs!F28,0) -> 2400
A26: =IF(Inputs!A29=""," (add label in Inputs)",Inputs!A29) -> (add label in Inputs) | B26: =IFERROR(Inputs!B29,0) -> 0 | C26: =IFERROR(Inputs!C29,0) -> 0 | D26: =IFERROR(Inputs!D29,0) -> 0 | E26: =IFERROR(Inputs!E29,0) -> 0 | F26: =IFERROR(Inputs!F29,0) -> 0
A27: =IF(Inputs!A30=""," (add label in Inputs)",Inputs!A30) -> (add label in Inputs) | B27: =IFERROR(Inputs!B30,0) -> 0 | C27: =IFERROR(Inputs!C30,0) -> 0 | D27: =IFERROR(Inputs!D30,0) -> 0 | E27: =IFERROR(Inputs!E30,0) -> 0 | F27: =IFERROR(Inputs!F30,0) -> 0
A28: =IF(Inputs!A31=""," (add label in Inputs)",Inputs!A31) -> (add label in Inputs) | B28: =IFERROR(Inputs!B31,0) -> 0 | C28: =IFERROR(Inputs!C31,0) -> 0 | D28: =IFERROR(Inputs!D31,0) -> 0 | E28: =IFERROR(Inputs!E31,0) -> 0 | F28: =IFERROR(Inputs!F31,0) -> 0
A29: Depreciation & Investment Expense [AUTO] | B29: =Inputs!B32 -> 5300 | C29: =Inputs!C32 -> 5300 | D29: =Inputs!D32 -> 6300 | E29: =Inputs!E32 -> 6300 | F29: =Inputs!F32 -> 7300
A30: Total Fixed Costs incl. Depreciation | B30: =Inputs!B33 -> 71300 | C30: =Inputs!C33 -> 71300 | D30: =Inputs!D33 -> 72300 | E30: =Inputs!E33 -> 84300 | F30: =Inputs!F33 -> 85300
A32: OPERATING PROFIT (EBIT) | B32: =B18-B30 -> -53800 | C32: =C18-C30 -> -45575 | D32: =D18-D30 -> 347280 | E32: =E18-E30 -> 492622.5 | F32: =F18-F30 -> 1263130
A33: Operating Margin (%) | B33: =IFERROR(B32/B9,0) -> -0.71733333 | C33: =IFERROR(C32/C9,0) -> -0.41337868 | D33: =IFERROR(D32/D9,0) -> 0.51040564 | E33: =IFERROR(E32/E9,0) -> 0.52655924 | F33: =IFERROR(F32/F9,0) -> 0.62895484
A35: Cumulative Operating Profit | B35: =B32 -> -53800 | C35: =B35+C32 -> -99375 | D35: =C35+D32 -> 247905 | E35: =D35+E32 -> 740527.5 | F35: =E35+F32 -> 2003657.5
A38: — Chart Data —
B39: Year 1 | C39: Year 2 | D39: Year 3 | E39: Year 4 | F39: Year 5
A40: Revenue | B40: =B9 -> 75000 | C40: =C9 -> 110250 | D40: =D9 -> 680400 | E40: =E9 -> 935550 | F40: =F9 -> 2008300
A41: Variable Costs | B41: =B17 -> 57500 | C41: =C17 -> 84525 | D41: =D17 -> 260820 | E41: =E17 -> 358627.5 | F41: =F17 -> 659870
A42: Fixed Costs incl. Depr | B42: =B30 -> 71300 | C42: =C30 -> 71300 | D42: =D30 -> 72300 | E42: =E30 -> 84300 | F42: =F30 -> 85300
A43: Op. Profit | B43: =B32 -> -53800 | C43: =C32 -> -45575 | D43: =D32 -> 347280 | E43: =E32 -> 492622.5 | F43: =F32 -> 1263130
A44: Cumul. Profit | B44: =B35 -> -53800 | C44: =C35 -> -99375 | D44: =D35 -> 247905 | E44: =E35 -> 740527.5 | F44: =F35 -> 2003657.5

Sheet BEP
A1: BREAK-EVEN POINT (BEP) ANALYSIS — 5-YEAR VIEW
A2: BEP = minimum units you must sell to cover ALL costs. Above BEP = profit. Below BEP = loss.
A3: Item | B3: Year 1 | C3: Year 2 | D3: Year 3 | E3: Year 4 | F3: Year 5
A4: COST STRUCTURE
A5: Total Fixed Costs incl. Depreciation | B5: =Inputs!B33 -> 71300 | C5: =Inputs!C33 -> 71300 | D5: =Inputs!D33 -> 72300 | E5: =Inputs!E33 -> 84300 | F5: =Inputs!F33 -> 85300
A6: Variable Cost per Unit | B6: =Inputs!B21 -> 11.5 | C6: =Inputs!C21 -> 11.5 | D6: =Inputs!D21 -> 11.5 | E6: =Inputs!E21 -> 11.5 | F6: =Inputs!F21 -> 11.5
A7: Unit Selling Price | B7: =Inputs!B9 -> 15 | C7: =Inputs!C9 -> 15 | D7: =Inputs!D9 -> 30 | E7: =Inputs!E9 -> 30 | F7: =Inputs!F9 -> 35
A8: Contribution Margin per Unit (Price − VC) | B8: =B7-B6 -> 3.5 | C8: =C7-C6 -> 3.5 | D8: =D7-D6 -> 18.5 | E8: =E7-E6 -> 18.5 | F8: =F7-F6 -> 23.5
A9: Contribution Margin Ratio (%) | B9: =IFERROR(B8/B7,0) -> 0.23333333 | C9: =IFERROR(C8/C7,0) -> 0.23333333 | D9: =IFERROR(D8/D7,0) -> 0.61666667 | E9: =IFERROR(E8/E7,0) -> 0.61666667 | F9: =IFERROR(F8/F7,0) -> 0.67142857
A10: BREAK-EVEN POINT
A11: 🎯 Minimum Units to Sell (BEP) | B11: =IFERROR(CEILING(B5/B8,1),0) -> 20372 | C11: =IFERROR(CEILING(C5/C8,1),0) -> 20372 | D11: =IFERROR(CEILING(D5/D8,1),0) -> 3909 | E11: =IFERROR(CEILING(E5/E8,1),0) -> 4557 | F11: =IFERROR(CEILING(F5/F8,1),0) -> 3630
A12: 🎯 Minimum Revenue to Achieve (BEP $) | B12: =IFERROR(B11*B7,0) -> 305580 | C12: =IFERROR(C11*C7,0) -> 305580 | D12: =IFERROR(D11*D7,0) -> 117270 | E12: =IFERROR(E11*E7,0) -> 136710 | F12: =IFERROR(F11*F7,0) -> 127050
A13: YOUR PERFORMANCE vs. BEP
A14: Your Target Units Sold | B14: =PL!B7 -> 5000 | C14: =PL!C7 -> 7350 | D14: =PL!D7 -> 22680 | E14: =PL!E7 -> 31185 | F14: =PL!F7 -> 57380
A15: Safety Margin (Units above BEP) | B15: =B14-B11 -> -15372 | C15: =C14-C11 -> -13022 | D15: =D14-D11 -> 18771 | E15: =E14-E11 -> 26628 | F15: =F14-F11 -> 53750
A16: Safety Margin (%) | B16: =IFERROR(B15/B14,0) -> -3.0744 | C16: =IFERROR(C15/C14,0) -> -1.7717007 | D16: =IFERROR(D15/D14,0) -> 0.8276455 | E16: =IFERROR(E15/E14,0) -> 0.85387205 | F16: =IFERROR(F15/F14,0) -> 0.93673754
A17: Operating Profit (EBIT) | B17: =PL!B32 -> -53800 | C17: =PL!C32 -> -45575 | D17: =PL!D32 -> 347280 | E17: =PL!E32 -> 492622.5 | F17: =PL!F32 -> 1263130
A18: Status | B18: =IF(B14>B11,"ABOVE BEP ✅","BELOW BEP ❌") -> BELOW BEP ❌ | C18: =IF(C14>C11,"ABOVE BEP ✅","BELOW BEP ❌") -> BELOW BEP ❌ | D18: =IF(D14>D11,"ABOVE BEP ✅","BELOW BEP ❌") -> ABOVE BEP ✅ | E18: =IF(E14>E11,"ABOVE BEP ✅","BELOW BEP ❌") -> ABOVE BEP ✅ | F18: =IF(F14>F11,"ABOVE BEP ✅","BELOW BEP ❌") -> ABOVE BEP ✅
A20: — BEP Chart Data Year 1 — | H20: =IFERROR(CEILING(B11/10,10),50) -> 2040
A21: Units | B21: Total Revenue ($) | C21: Total Costs ($) | D21: Fixed Costs ($)
A22: =0*$H$20 -> 0 | B22: =A22*Inputs!$B$9 -> 0 | C22: =$B$5+A22*$B$6 -> 71300 | D22: =$B$5 -> 71300
A23: =1*$H$20 -> 2040 | B23: =A23*Inputs!$B$9 -> 30600 | C23: =$B$5+A23*$B$6 -> 94760 | D23: =$B$5 -> 71300
A24: =2*$H$20 -> 4080 | B24: =A24*Inputs!$B$9 -> 61200 | C24: =$B$5+A24*$B$6 -> 118220 | D24: =$B$5 -> 71300
A25: =3*$H$20 -> 6120 | B25: =A25*Inputs!$B$9 -> 91800 | C25: =$B$5+A25*$B$6 -> 141680 | D25: =$B$5 -> 71300
A26: =4*$H$20 -> 8160 | B26: =A26*Inputs!$B$9 -> 122400 | C26: =$B$5+A26*$B$6 -> 165140 | D26: =$B$5 -> 71300
A27: =5*$H$20 -> 10200 | B27: =A27*Inputs!$B$9 -> 153000 | C27: =$B$5+A27*$B$6 -> 188600 | D27: =$B$5 -> 71300
A28: =6*$H$20 -> 12240 | B28: =A28*Inputs!$B$9 -> 183600 | C28: =$B$5+A28*$B$6 -> 212060 | D28: =$B$5 -> 71300
A29: =7*$H$20 -> 14280 | B29: =A29*Inputs!$B$9 -> 214200 | C29: =$B$5+A29*$B$6 -> 235520 | D29: =$B$5 -> 71300
A30: =8*$H$20 -> 16320 | B30: =A30*Inputs!$B$9 -> 244800 | C30: =$B$5+A30*$B$6 -> 258980 | D30: =$B$5 -> 71300
A31: =9*$H$20 -> 18360 | B31: =A31*Inputs!$B$9 -> 275400 | C31: =$B$5+A31*$B$6 -> 282440 | D31: =$B$5 -> 71300
A32: =10*$H$20 -> 20400 | B32: =A32*Inputs!$B$9 -> 306000 | C32: =$B$5+A32*$B$6 -> 305900 | D32: =$B$5 -> 71300
A33: =11*$H$20 -> 22440 | B33: =A33*Inputs!$B$9 -> 336600 | C33: =$B$5+A33*$B$6 -> 329360 | D33: =$B$5 -> 71300
A34: =12*$H$20 -> 24480 | B34: =A34*Inputs!$B$9 -> 367200 | C34: =$B$5+A34*$B$6 -> 352820 | D34: =$B$5 -> 71300
A35: =13*$H$20 -> 26520 | B35: =A35*Inputs!$B$9 -> 397800 | C35: =$B$5+A35*$B$6 -> 376280 | D35: =$B$5 -> 71300
A36: =14*$H$20 -> 28560 | B36: =A36*Inputs!$B$9 -> 428400 | C36: =$B$5+A36*$B$6 -> 399740 | D36: =$B$5 -> 71300
A37: =15*$H$20 -> 30600 | B37: =A37*Inputs!$B$9 -> 459000 | C37: =$B$5+A37*$B$6 -> 423200 | D37: =$B$5 -> 71300
A38: =16*$H$20 -> 32640 | B38: =A38*Inputs!$B$9 -> 489600 | C38: =$B$5+A38*$B$6 -> 446660 | D38: =$B$5 -> 71300
A39: =17*$H$20 -> 34680 | B39: =A39*Inputs!$B$9 -> 520200 | C39: =$B$5+A39*$B$6 -> 470120 | D39: =$B$5 -> 71300
A40: =18*$H$20 -> 36720 | B40: =A40*Inputs!$B$9 -> 550800 | C40: =$B$5+A40*$B$6 -> 493580 | D40: =$B$5 -> 71300
A41: =19*$H$20 -> 38760 | B41: =A41*Inputs!$B$9 -> 581400 | C41: =$B$5+A41*$B$6 -> 517040 | D41: =$B$5 -> 71300
...
